{
  "comments": [
    {
      "key": {
        "uuid": "8fa44527_388a22ab",
        "filename": "src/main/java/com/googlesource/gerrit/plugins/websession/flatfile/FlatFileWebSessionCacheCleaner.java",
        "patchSetId": 2
      },
      "lineNbr": 53,
      "author": {
        "id": 1003883
      },
      "writtenOn": "2020-05-15T21:51:05Z",
      "side": 1,
      "message": "This would be better inside the iteration to prevent a bad entry from preventing the rest from being cleaned up.",
      "range": {
        "startLine": 53,
        "startChar": 8,
        "endLine": 53,
        "endChar": 14
      },
      "revId": "2f6ae90e3132f852bd689f20c84f3711852d14f9",
      "serverId": "173816e5-2b9a-37c3-8a2e-48639d4f1153",
      "unresolved": true
    },
    {
      "key": {
        "uuid": "9b6d762f_2b598c2d",
        "filename": "src/main/java/com/googlesource/gerrit/plugins/websession/flatfile/FlatFileWebSessionCacheCleaner.java",
        "patchSetId": 2
      },
      "lineNbr": 53,
      "author": {
        "id": 1002666
      },
      "writtenOn": "2020-05-15T21:55:03Z",
      "side": 1,
      "message": "I think that would also be good, but it\u0027s not the intent here. The intent is to ensure nothing in run() throws exceptions. Perhaps the loggers should go inside the try to show that clearer?",
      "parentUuid": "8fa44527_388a22ab",
      "range": {
        "startLine": 53,
        "startChar": 8,
        "endLine": 53,
        "endChar": 14
      },
      "revId": "2f6ae90e3132f852bd689f20c84f3711852d14f9",
      "serverId": "173816e5-2b9a-37c3-8a2e-48639d4f1153",
      "unresolved": true
    },
    {
      "key": {
        "uuid": "0738dc50_40277b97",
        "filename": "src/main/java/com/googlesource/gerrit/plugins/websession/flatfile/FlatFileWebSessionCacheCleaner.java",
        "patchSetId": 2
      },
      "lineNbr": 53,
      "author": {
        "id": 1003883
      },
      "writtenOn": "2020-05-16T01:29:20Z",
      "side": 1,
      "message": "I think that the bigger intent should be fixed in core since core wraps all runnables in a Task, it could catch these exceptions for everyone. The problem here is that with this fix, you still are likely to get stuck and potentially be worse off trying to cleanup something uncleanable over and over.",
      "parentUuid": "9b6d762f_2b598c2d",
      "range": {
        "startLine": 53,
        "startChar": 8,
        "endLine": 53,
        "endChar": 14
      },
      "revId": "2f6ae90e3132f852bd689f20c84f3711852d14f9",
      "serverId": "173816e5-2b9a-37c3-8a2e-48639d4f1153",
      "unresolved": true
    }
  ]
}